Traceback (most recent call last):
  File "/opt/anaconda3/envs/DA2022/lib/python3.10/site-packages/jupyter_cache/executors/utils.py", line 51, in single_nb_execution
    executenb(
  File "/opt/anaconda3/envs/DA2022/lib/python3.10/site-packages/nbclient/client.py", line 1204, in execute
    return NotebookClient(nb=nb, resources=resources, km=km, **kwargs).execute()
  File "/opt/anaconda3/envs/DA2022/lib/python3.10/site-packages/nbclient/util.py", line 84, in wrapped
    return just_run(coro(*args, **kwargs))
  File "/opt/anaconda3/envs/DA2022/lib/python3.10/site-packages/nbclient/util.py", line 62, in just_run
    return loop.run_until_complete(coro)
  File "/opt/anaconda3/envs/DA2022/lib/python3.10/asyncio/base_events.py", line 641, in run_until_complete
    return future.result()
  File "/opt/anaconda3/envs/DA2022/lib/python3.10/site-packages/nbclient/client.py", line 663, in async_execute
    await self.async_execute_cell(
  File "/opt/anaconda3/envs/DA2022/lib/python3.10/site-packages/nbclient/client.py", line 965, in async_execute_cell
    await self._check_raise_for_error(cell, cell_index, exec_reply)
  File "/opt/anaconda3/envs/DA2022/lib/python3.10/site-packages/nbclient/client.py", line 862, in _check_raise_for_error
    raise CellExecutionError.from_cell_and_msg(cell, exec_reply_content)
nbclient.exceptions.CellExecutionError: An error occurred while executing the following cell:
------------------
```{code-cell} ipython3
---
render:
  image:
    alt: fun-fish
    classes: shadow bg-primary
  figure:
    caption: |
      Hey everyone its **party** time!
    name: fun-fish
---
f3
```
------------------

[0;36m  Input [0;32mIn [16][0;36m[0m
[0;31m    ```{code-cell} ipython3[0m
[0m    ^[0m
[0;31mSyntaxError[0m[0;31m:[0m invalid syntax

SyntaxError: invalid syntax (436472225.py, line 1)

